<?xml version="1.0"?>

<robot name="hexapod">

<link name="base_link">
  <visual>
   <geometry>
      <box size="0.01 0.01 0.01"/>
   </geometry>
   <material name="black">
     <color rgba="0 0 0 100"/>
   </material>
  </visual>
</link>

<link name="body">
  <visual>
   <geometry>
     <cylinder length="0.1" radius="0.18"/>
   </geometry>
   <material name="black">
     <color rgba="0 0 0 100"/>
   </material>
  </visual>
</link>

<joint name="body" type="fixed">
  <axis xyz="0 0 1"/>
  <parent link="base_link"/>
  <child link="body"/>
  <origin rpy="0 0 0" xyz="0 0 0.5"/>
</joint>


<!--first-leg-->
<link name="bridge1">
  <visual>
    <origin xyz="0 0 0.0465" rpy="0 0 0"/>
    <geometry>
      <cylinder length="0.093" radius="0.01"/>
    </geometry>
    <material name="white">
      <color rgba="255 255 255 1"/>
    </material>
  </visual>
</link>
<joint name="bridge1" type="fixed">
  <axis xyz="0 0 1"/>
  <parent link="body"/>
  <child link="bridge1"/>
  <origin rpy="0 1.57075 0" xyz="0.18 0 0"/>
</joint>
      
<link name="leg1_roll">
  <visual>
    <origin xyz="0 0 0.072445" rpy="0 0 0"/>
    <geometry>
      <cylinder length="0.14489" radius="0.02"/>
    </geometry>
    <material name="blue">
      <color rgba="0 0 255 1"/>
    </material>
  </visual>
</link>
<joint name="leg1_roll" type="revolute">
  <axis xyz="1 0 0"/>
  <limit effort="300" lower="-0.78540" upper="0.78540" velocity="1"/>
  <parent link="bridge1"/>
  <child link="leg1_roll"/>
  <origin rpy="0 0 0" xyz="0 0 0.093"/>
</joint>

<link name="leg1_pitch1">
  <visual>
    <origin xyz="0 0 0.082" rpy="0 0 0"/>
    <geometry>
      <cylinder length="0.164" radius="0.02"/>
    </geometry>
    <material name="green">
      <color rgba="0 128 0 1"/>
    </material>
  </visual>
</link>
<joint name="leg1_pitch1" type="revolute">
  <axis xyz="0 1 0"/>
  <limit effort="300" lower="-0.78540" upper="0.78540" velocity="1"/>
  <parent link="leg1_roll"/>
  <child link="leg1_pitch1"/>
  <origin rpy="0 0.78540 0" xyz="0 0 0.14489"/>
</joint>

<link name="leg1_pitch2">
  <visual>
    <origin xyz="0 0 0.0785" rpy="0 0 0"/>
    <geometry>
      <cylinder length="0.157" radius="0.02"/>
    </geometry>
    <material name="black">
      <color rgba="0 0 0 1"/>
    </material>
  </visual>
</link>
<joint name="leg1_pitch2" type="revolute">
  <axis xyz="0 1 0"/>
  <limit effort="300" lower="-0.78540" upper="0.78540" velocity="1"/>
  <parent link="leg1_pitch1"/>
  <child link="leg1_pitch2"/>
  <origin rpy="0 0.78540 0" xyz="0 0 0.164"/>
</joint>

<link name="stick1">
  <visual>
    <origin xyz="0 0 0.157" rpy="0 0 0"/>
    <geometry>
      <cylinder length="0.01" radius="0.05"/>
    </geometry>
    <material name="yellow">
      <color rgba="255 255 0 1"/>
    </material>
  </visual>
</link>
<joint name="stick1" type="floating">
  <origin xyz="0 0 0" rpy="0 0 0"/>
   <parent link="leg1_pitch2"/>
    <child link="stick1"/>

 </joint>


</robot>
