<?xml version="1.0"?>

<robot name="hexapod">

<link name="base_link">
  <visual>
   <geometry>
      <box size="0.01 0.01 0.01"/>
   </geometry>
   <material name="black">
     <color rgba="0 0 0 100"/>
   </material>
  </visual>
</link>
<!--body-->
<link name="body">
  
<visual>
   <geometry>
     <cylinder length="0.1" radius="0.18"/>
   </geometry>
   <material name="black">
     <color rgba="0 0 0 100"/>
   </material>
  </visual>
   
 <collision>
      <origin xyz="0 0 0" rpy="0 0 0"/>
      <geometry>
     <cylinder length="0.1" radius="0.18"/>
      </geometry>
    </collision>

<inertial>
      <origin xyz="0 0 0" rpy="0 0 0"/>
      <mass value="1"/>
      <inertia
        ixx="0.01" ixy="0.0" ixz="0.0"
        iyy="0.01" iyz="0.0"
        izz="0.01"/>
    </inertial>
</link>
  <gazebo reference="body">
    <material>Gazebo/Blue</material>
  </gazebo>

<joint name="body" type="fixed">
  <axis xyz="0 0 1"/>
  <parent link="base_link"/>
  <child link="body"/>
  <origin rpy="0 0 0" xyz="0 0 0.5"/>
</joint>


<!--first-leg-->
<link name="bridge1">
  <visual>
    <origin xyz="0 0 0.0465" rpy="0 0 0"/>
    <geometry>
      <cylinder length="0.093" radius="0.01"/>
    </geometry>
    <material name="white">
      <color rgba="255 255 255 1"/>
    </material>
  </visual>
  <inertial>
      <origin xyz="0 0 0.0465" rpy="0 0 0"/>
      <mass value="1"/>
      <inertia
        ixx="0.01" ixy="0.0" ixz="0.0"
        iyy="0.01" iyz="0.0"
        izz="0.01"/>
    </inertial>
  <collision>
    <origin xyz="0 0 0.0465" rpy="0 0 0"/>
    <geometry>
      <cylinder length="0.093" radius="0.01"/>
    </geometry>
  </collision>
</link>
  <gazebo reference="bridge1">
    <material>Gazebo/white</material>
  </gazebo>
<joint name="bridge1" type="fixed">
  <axis xyz="0 0 1"/>
  <parent link="body"/>
  <child link="bridge1"/>
  <origin rpy="0 1.57075 0" xyz="0.18 0 0"/>
</joint>





    
<link name="leg1_roll">
  <visual>
    <origin xyz="-0.072445 0 0" rpy="0 0 0"/>
    <geometry>
      <box size="0.14489 0.04 0.04"/>
    </geometry>
    <material name="blue">
      <color rgba="0 0 255 1"/>
    </material>
  </visual>
  <inertial>
    <origin xyz="-0.072445 0 0" rpy="0 0 0"/>
      <mass value="1"/>
      <inertia
        ixx="0.01" ixy="0.0" ixz="0.0"
        iyy="0.01" iyz="0.0"
        izz="0.01"/>
    </inertial>
  <collision>
    <origin xyz="-0.072445 0 0" rpy="0 0 0"/>
    <geometry>
      <box size="0.14489 0.04 0.04"/>
    </geometry>
  </collision>
</link>
  <gazebo reference="leg1_roll">
    <material>Gazebo/Blue</material>
  </gazebo>
<joint name="leg1_roll" type="revolute">
  <axis xyz="0 0 1"/>
  <limit effort="300" lower="-0.78540" upper="0.78540" velocity="1"/>
  <parent link="bridge1"/>
  <child link="leg1_roll"/>
  <origin rpy="0 1.57075 0" xyz="0 0 0.093"/>
</joint>

  <transmission name="tran1">
    <type>transmission_interface/SimpleTransmission</type>
    <joint name="leg1_roll">
      <hardwareInterface>EffortJointInterface</hardwareInterface>
    </joint>
    <actuator name="leg1_roll_motor">
      <hardwareInterface>EffortJointInterface</hardwareInterface>
      <mechanicalReduction>1</mechanicalReduction>
    </actuator>
  </transmission>
  <gazebo>
     <plugin name="gazebo_ros_control" filename="libgazebo_ros_control.so">
       <robotNamespace>/hexapod</robotNamespace>
     </plugin>
  </gazebo>
  <gazebo>
     <plugin name="joint_state_publisher" filename="libgazebo_ros_joint_state_publisher.so">
       <jointName>leg1_roll</jointName>
     </plugin>
  </gazebo>




</robot>

